Workbook

Sheet Mayo 24
A1: Aromas y Sabores del Mediterráneo S.L.
A2: Sumas y Saldos Mayo 24
A4: Subcuenta | B4: Concepto | C4: Saldo Anterior | D4: Mvto. Debe | E4: Mvto. Haber | F4: Saldo Actual
A5: 100 | B5: Capital social | C5: 2419.65 | D5: 12067.93 | E5: 52074.76 | F5: -37587.18
A6: 129 | B6: Resultado del ejercicio | C6: -4116.66 | D6: 42870.56 | E6: 29255.11 | F6: 9498.79
A7: 281 | B7: Amortización acumulada del inmovilizado material | C7: -4492.03 | D7: 40594.86 | E7: 2999.65 | F7: 33103.18
A8: 4720 | B8: H.P. IVA SOPORTADO | C8: 5274.79 | D8: 5588.43 | E8: 7257.04 | F8: 3606.18
A9: 4770 | B9: H.P. IVA REPERCUTIDO | C9: 5037.5 | D9: 66148.17 | E9: 9904.16 | F9: 61281.51
A10: 4751 | B10: H.P. Acreedora por IS | C10: -195.79 | D10: 50194.66 | E10: 75816.72 | F10: -25817.85
A11: 4752 | B11: H.P. Acreedora por IRPF | C11: 9004.68 | D11: 31734.44 | E11: 78100.41 | F11: -37361.29
A12: 4760 | B12: Organismos de la Seguridad Social acreedores | C12: -4788.85 | D12: 68677.48 | E12: 23168.74 | F12: 40719.89
A13: 570 | B13: Caja, euros | C13: -2249.37 | D13: 9423.38 | E13: 24678.55 | F13: -17504.54
A14: 572 | B14: Bancos e instituciones de crédito c/c vista, euros | C14: 15219.29 | D14: 14458.11 | E14: 46528.01 | F14: -16850.61
A15: 600 | B15: Compras de mercaderías | C15: 10611.75 | D15: 29791.8 | E15: 43819.56 | F15: -3416.01
A16: 621 | B16: Arrendamientos y cánones | C16: -4367.49 | D16: 4768.09 | E16: 16476.7 | F16: -16076.1
... A59: 4100000004 | B59: PUBLICIDAD ALBA EVENTOS | C59: 591.75 | D59: 22001.99 | E59: 10022.52 | F59: 12571.22
A60: 99000 | B60: FÓRMULA EXTERNA 0 | C60: =SUMIFS('Mayo 25'!$E:$E,'Mayo 25'!$A:$A,A10) | D60: =+AB10+BK10 | E60: =SUMIFS('Septiembre 25'!$F:$F,'Septiembre 25'!$A:$A,A20) | F60: =H10+AQ10-SUMIFS('Octubre 25'!$F:$F,'Octubre 25'!$A:$A,A10)
A61: 99001 | B61: FÓRMULA EXTERNA 1 | C61: =SUMIFS('Mayo 25'!$E:$E,'Mayo 25'!$A:$A,A11) | D61: =+AB11+BK11 | E61: =SUMIFS('Septiembre 25'!$F:$F,'Septiembre 25'!$A:$A,A21) | F61: =H11+AQ11-SUMIFS('Octubre 25'!$F:$F,'Octubre 25'!$A:$A,A11)
A62: 99002 | B62: FÓRMULA EXTERNA 2 | C62: =SUMIFS('Mayo 25'!$E:$E,'Mayo 25'!$A:$A,A12) | D62: =+AB12+BK12 | E62: =SUMIFS('Septiembre 25'!$F:$F,'Septiembre 25'!$A:$A,A22) | F62: =H12+AQ12-SUMIFS('Octubre 25'!$F:$F,'Octubre 25'!$A:$A,A12)
A63: 99003 | B63: FÓRMULA EXTERNA 3 | C63: =SUMIFS('Mayo 25'!$E:$E,'Mayo 25'!$A:$A,A13) | D63: =+AB13+BK13 | E63: =SUMIFS('Septiembre 25'!$F:$F,'Septiembre 25'!$A:$A,A23) | F63: =H13+AQ13-SUMIFS('Octubre 25'!$F:$F,'Octubre 25'!$A:$A,A13)
A64: 99004 | B64: FÓRMULA EXTERNA 4 | C64: =SUMIFS('Mayo 25'!$E:$E,'Mayo 25'!$A:$A,A14) | D64: =+AB14+BK14 | E64: =SUMIFS('Septiembre 25'!$F:$F,'Septiembre 25'!$A:$A,A24) | F64: =H14+AQ14-SUMIFS('Octubre 25'!$F:$F,'Octubre 25'!$A:$A,A14)

Sheet Junio 24
A1: Aromas y Sabores del Mediterráneo S.L.
A2: Sumas y Saldos Junio 24
A4: Subcuenta | B4: Concepto | C4: Saldo Anterior | D4: Mvto. Debe | E4: Mvto. Haber | F4: Saldo Actual
A5: 100 | B5: Capital social | C5: 14070.39 | D5: 42607.39 | E5: 62324.39 | F5: -5646.61
A6: 129 | B6: Resultado del ejercicio | C6: 2571.29 | D6: 17843.33 | E6: 64920.9 | F6: -44506.28
A7: 281 | B7: Amortización acumulada del inmovilizado material | C7: 19608.08 | D7: 68210.3 | E7: 64486.29 | F7: 23332.09
A8: 4720 | B8: H.P. IVA SOPORTADO | C8: 15276.66 | D8: 59189.84 | E8: 18139.16 | F8: 56327.34
A9: 4770 | B9: H.P. IVA REPERCUTIDO | C9: 7458.61 | D9: 28445 | E9: 2318.41 | F9: 33585.2
A10: 4751 | B10: H.P. Acreedora por IS | C10: -5273.64 | D10: 22353.48 | E10: 20733.95 | F10: -3654.11
A11: 4752 | B11: H.P. Acreedora por IRPF | C11: 12005.57 | D11: 76521.21 | E11: 35778.21 | F11: 52748.57
A12: 4760 | B12: Organismos de la Seguridad Social acreedores | C12: 18362.55 | D12: 79043.04 | E12: 76400.05 | F12: 21005.54
A13: 570 | B13: Caja, euros | C13: 3480.53 | D13: 17636.99 | E13: 18147.67 | F13: 2969.85
A14: 572 | B14: Bancos e instituciones de crédito c/c vista, euros | C14: -885.64 | D14: 16349.87 | E14: 49925.31 | F14: -34461.08
A15: 600 | B15: Compras de mercaderías | C15: 17408.02 | D15: 67234.84 | E15: 38357.87 | F15: 46284.99
A16: 621 | B16: Arrendamientos y cánones | C16: 10977.43 | D16: 63971.5 | E16: 6782.28 | F16: 68166.65
... A59: 4100000004 | B59: PUBLICIDAD ALBA EVENTOS | C59: 14709.12 | D59: 47301.78 | E59: 58301.76 | F59: 3709.14
A60: 99000 | B60: FÓRMULA EXTERNA 0 | C60: =SUMIFS('Mayo 25'!$E:$E,'Mayo 25'!$A:$A,A10) | D60: =+AB10+BK10 | E60: =SUMIFS('Septiembre 25'!$F:$F,'Septiembre 25'!$A:$A,A20) | F60: =H10+AQ10-SUMIFS('Octubre 25'!$F:$F,'Octubre 25'!$A:$A,A10)
A61: 99001 | B61: FÓRMULA EXTERNA 1 | C61: =SUMIFS('Mayo 25'!$E:$E,'Mayo 25'!$A:$A,A11) | D61: =+AB11+BK11 | E61: =SUMIFS('Septiembre 25'!$F:$F,'Septiembre 25'!$A:$A,A21) | F61: =H11+AQ11-SUMIFS('Octubre 25'!$F:$F,'Octubre 25'!$A:$A,A11)
A62: 99002 | B62: FÓRMULA EXTERNA 2 | C62: =SUMIFS('Mayo 25'!$E:$E,'Mayo 25'!$A:$A,A12) | D62: =+AB12+BK12 | E62: =SUMIFS('Septiembre 25'!$F:$F,'Septiembre 25'!$A:$A,A22) | F62: =H12+AQ12-SUMIFS('Octubre 25'!$F:$F,'Octubre 25'!$A:$A,A12)
A63: 99003 | B63: FÓRMULA EXTERNA 3 | C63: =SUMIFS('Mayo 25'!$E:$E,'Mayo 25'!$A:$A,A13) | D63: =+AB13+BK13 | E63: =SUMIFS('Septiembre 25'!$F:$F,'Septiembre 25'!$A:$A,A23) | F63: =H13+AQ13-SUMIFS('Octubre 25'!$F:$F,'Octubre 25'!$A:$A,A13)
A64: 99004 | B64: FÓRMULA EXTERNA 4 | C64: =SUMIFS('Mayo 25'!$E:$E,'Mayo 25'!$A:$A,A14) | D64: =+AB14+BK14 | E64: =SUMIFS('Septiembre 25'!$F:$F,'Septiembre 25'!$A:$A,A24) | F64: =H14+AQ14-SUMIFS('Octubre 25'!$F:$F,'Octubre 25'!$A:$A,A14)

Sheet Septiembre 24
A1: Aromas y Sabores del Mediterráneo S.L.
A2: Sumas y Saldos Septiembre 24
A4: Subcuenta | B4: Concepto | C4: Saldo Anterior | D4: Mvto. Debe | E4: Mvto. Haber | F4: Saldo Actual
A5: 100 | B5: Capital social | C5: -3275.73 | D5: 21245.14 | E5: 3167.06 | F5: 14802.35
A6: 129 | B6: Resultado del ejercicio | C6: 14253.93 | D6: 21635.69 | E6: 10364.44 | F6: 25525.18
A7: 281 | B7: Amortización acumulada del inmovilizado material | C7: 4978.61 | D7: 72913.11 | E7: 65518.32 | F7: 12373.4
A8: 4720 | B8: H.P. IVA SOPORTADO | C8: 723.83 | D8: 11949.44 | E8: 73533.72 | F8: -60860.45
A9: 4770 | B9: H.P. IVA REPERCUTIDO | C9: 8835.47 | D9: 56033.4 | E9: 7156.98 | F9: 57711.89
A10: 4751 | B10: H.P. Acreedora por IS | C10: -4504.31 | D10: 55056.45 | E10: 34025.36 | F10: 16526.78
A11: 4752 | B11: H.P. Acreedora por IRPF | C11: -4117.23 | D11: 75067.98 | E11: 50755.16 | F11: 20195.59
A12: 4760 | B12: Organismos de la Seguridad Social acreedores | C12: 14842.34 | D12: 6699.4 | E12: 68498.29 | F12: -46956.55
A13: 570 | B13: Caja, euros | C13: -4267.81 | D13: 69022 | E13: 36301.88 | F13: 28452.31
A14: 572 | B14: Bancos e instituciones de crédito c/c vista, euros | C14: 2817.95 | D14: 44245.13 | E14: 74133.54 | F14: -27070.46
A15: 600 | B15: Compras de mercaderías | C15: 964.35 | D15: 10337.98 | E15: 42153.2 | F15: -30850.87
A16: 621 | B16: Arrendamientos y cánones | C16: 199.34 | D16: 8756.12 | E16: 12915.93 | F16: -3960.47
... A59: 4100000004 | B59: PUBLICIDAD ALBA EVENTOS | C59: 4840.7 | D59: 41021.79 | E59: 46018.21 | F59: -155.72
A60: 99000 | B60: FÓRMULA EXTERNA 0 | C60: =SUMIFS('Mayo 25'!$E:$E,'Mayo 25'!$A:$A,A10) | D60: =+AB10+BK10 | E60: =SUMIFS('Septiembre 25'!$F:$F,'Septiembre 25'!$A:$A,A20) | F60: =H10+AQ10-SUMIFS('Octubre 25'!$F:$F,'Octubre 25'!$A:$A,A10)
A61: 99001 | B61: FÓRMULA EXTERNA 1 | C61: =SUMIFS('Mayo 25'!$E:$E,'Mayo 25'!$A:$A,A11) | D61: =+AB11+BK11 | E61: =SUMIFS('Septiembre 25'!$F:$F,'Septiembre 25'!$A:$A,A21) | F61: =H11+AQ11-SUMIFS('Octubre 25'!$F:$F,'Octubre 25'!$A:$A,A11)
A62: 99002 | B62: FÓRMULA EXTERNA 2 | C62: =SUMIFS('Mayo 25'!$E:$E,'Mayo 25'!$A:$A,A12) | D62: =+AB12+BK12 | E62: =SUMIFS('Septiembre 25'!$F:$F,'Septiembre 25'!$A:$A,A22) | F62: =H12+AQ12-SUMIFS('Octubre 25'!$F:$F,'Octubre 25'!$A:$A,A12)
A63: 99003 | B63: FÓRMULA EXTERNA 3 | C63: =SUMIFS('Mayo 25'!$E:$E,'Mayo 25'!$A:$A,A13) | D63: =+AB13+BK13 | E63: =SUMIFS('Septiembre 25'!$F:$F,'Septiembre 25'!$A:$A,A23) | F63: =H13+AQ13-SUMIFS('Octubre 25'!$F:$F,'Octubre 25'!$A:$A,A13)
A64: 99004 | B64: FÓRMULA EXTERNA 4 | C64: =SUMIFS('Mayo 25'!$E:$E,'Mayo 25'!$A:$A,A14) | D64: =+AB14+BK14 | E64: =SUMIFS('Septiembre 25'!$F:$F,'Septiembre 25'!$A:$A,A24) | F64: =H14+AQ14-SUMIFS('Octubre 25'!$F:$F,'Octubre 25'!$A:$A,A14)

Sheet Octubre 24
A1: Aromas y Sabores del Mediterráneo S.L.
A2: Sumas y Saldos Octubre 24
A4: Subcuenta | B4: Concepto | C4: Saldo Anterior | D4: Mvto. Debe | E4: Mvto. Haber | F4: Saldo Actual
A5: 100 | B5: Capital social | C5: 10041.32 | D5: 51421.04 | E5: 6197.75 | F5: 55264.61
A6: 129 | B6: Resultado del ejercicio | C6: -2166.95 | D6: 20315.22 | E6: 59457.38 | F6: -41309.11
A7: 281 | B7: Amortización acumulada del inmovilizado material | C7: 1914.85 | D7: 45420.94 | E7: 997.54 | F7: 46338.25
A8: 4720 | B8: H.P. IVA SOPORTADO | C8: -4422.81 | D8: 21501.82 | E8: 53760.13 | F8: -36681.12
A9: 4770 | B9: H.P. IVA REPERCUTIDO | C9: 11996.81 | D9: 54056.61 | E9: 23268.52 | F9: 42784.9
A10: 4751 | B10: H.P. Acreedora por IS | C10: 7429.93 | D10: 37173.03 | E10: 37307.13 | F10: 7295.83
A11: 4752 | B11: H.P. Acreedora por IRPF | C11: -2918.93 | D11: 71493.03 | E11: 15940 | F11: 52634.1
A12: 4760 | B12: Organismos de la Seguridad Social acreedores | C12: 19431.27 | D12: 74900.35 | E12: 1400.36 | F12: 92931.26
A13: 570 | B13: Caja, euros | C13: 5933.24 | D13: 65591.82 | E13: 77448.66 | F13: -5923.6
A14: 572 | B14: Bancos e instituciones de crédito c/c vista, euros | C14: 5685.73 | D14: 21492.58 | E14: 16786.98 | F14: 10391.33
A15: 600 | B15: Compras de mercaderías | C15: 18585.27 | D15: 16856.7 | E15: 46517.79 | F15: -11075.82
A16: 621 | B16: Arrendamientos y cánones | C16: -2314.74 | D16: 41925.26 | E16: 76219.23 | F16: -36608.71
... A59: 4100000004 | B59: PUBLICIDAD ALBA EVENTOS | C59: 9573.84 | D59: 38840.89 | E59: 45888.03 | F59: 2526.7
A60: 99000 | B60: FÓRMULA EXTERNA 0 | C60: =SUMIFS('Mayo 25'!$E:$E,'Mayo 25'!$A:$A,A10) | D60: =+AB10+BK10 | E60: =SUMIFS('Septiembre 25'!$F:$F,'Septiembre 25'!$A:$A,A20) | F60: =H10+AQ10-SUMIFS('Octubre 25'!$F:$F,'Octubre 25'!$A:$A,A10)
A61: 99001 | B61: FÓRMULA EXTERNA 1 | C61: =SUMIFS('Mayo 25'!$E:$E,'Mayo 25'!$A:$A,A11) | D61: =+AB11+BK11 | E61: =SUMIFS('Septiembre 25'!$F:$F,'Septiembre 25'!$A:$A,A21) | F61: =H11+AQ11-SUMIFS('Octubre 25'!$F:$F,'Octubre 25'!$A:$A,A11)
A62: 99002 | B62: FÓRMULA EXTERNA 2 | C62: =SUMIFS('Mayo 25'!$E:$E,'Mayo 25'!$A:$A,A12) | D62: =+AB12+BK12 | E62: =SUMIFS('Septiembre 25'!$F:$F,'Septiembre 25'!$A:$A,A22) | F62: =H12+AQ12-SUMIFS('Octubre 25'!$F:$F,'Octubre 25'!$A:$A,A12)
A63: 99003 | B63: FÓRMULA EXTERNA 3 | C63: =SUMIFS('Mayo 25'!$E:$E,'Mayo 25'!$A:$A,A13) | D63: =+AB13+BK13 | E63: =SUMIFS('Septiembre 25'!$F:$F,'Septiembre 25'!$A:$A,A23) | F63: =H13+AQ13-SUMIFS('Octubre 25'!$F:$F,'Octubre 25'!$A:$A,A13)
A64: 99004 | B64: FÓRMULA EXTERNA 4 | C64: =SUMIFS('Mayo 25'!$E:$E,'Mayo 25'!$A:$A,A14) | D64: =+AB14+BK14 | E64: =SUMIFS('Septiembre 25'!$F:$F,'Septiembre 25'!$A:$A,A24) | F64: =H14+AQ14-SUMIFS('Octubre 25'!$F:$F,'Octubre 25'!$A:$A,A14)

Sheet Mayo 25
A1: Aromas y Sabores del Mediterráneo S.L.
A2: Sumas y Saldos Mayo 25
A4: Subcuenta | B4: Concepto | C4: Saldo Anterior | D4: Mvto. Debe | E4: Mvto. Haber | F4: Saldo Actual
A5: 100 | B5: Capital social | C5: 5890.45 | D5: 44120.07 | E5: 3163.7 | F5: 46846.82
A6: 129 | B6: Resultado del ejercicio | C6: 14339.76 | D6: 18606.15 | E6: 73593.61 | F6: -40647.7
A7: 281 | B7: Amortización acumulada del inmovilizado material | C7: 10783.15 | D7: 24302.58 | E7: 10237.35 | F7: 24848.38
A8: 4720 | B8: H.P. IVA SOPORTADO | C8: 546.64 | D8: 50903.29 | E8: 55886.55 | F8: -4436.62
A9: 4770 | B9: H.P. IVA REPERCUTIDO | C9: -3084.55 | D9: 5628.15 | E9: 41954.93 | F9: -39411.33
A10: 4751 | B10: H.P. Acreedora por IS | C10: 9155.17 | D10: 31046.56 | E10: 17886.64 | F10: 22315.09
A11: 4752 | B11: H.P. Acreedora por IRPF | C11: 9627.58 | D11: 836.93 | E11: 24121.7 | F11: -13657.19
A12: 4760 | B12: Organismos de la Seguridad Social acreedores | C12: 5977.96 | D12: 76715.2 | E12: 51566.05 | F12: 31127.11
A13: 570 | B13: Caja, euros | C13: 16978.12 | D13: 38024.34 | E13: 18781.45 | F13: 36221.01
A14: 572 | B14: Bancos e instituciones de crédito c/c vista, euros | C14: 423.52 | D14: 76849.14 | E14: 56372.29 | F14: 20900.37
A15: 600 | B15: Compras de mercaderías | C15: 1992.34 | D15: 1742.99 | E15: 39864.82 | F15: -36129.49
A16: 621 | B16: Arrendamientos y cánones | C16: 11536.04 | D16: 33601.27 | E16: 20580.49 | F16: 24556.82
... A59: 4100000004 | B59: PUBLICIDAD ALBA EVENTOS | C59: 9340.54 | D59: 26817.79 | E59: 14051.78 | F59: 22106.55
A60: 99000 | B60: FÓRMULA EXTERNA 0 | C60: =SUMIFS('Mayo 25'!$E:$E,'Mayo 25'!$A:$A,A10) | D60: =+AB10+BK10 | E60: =SUMIFS('Septiembre 25'!$F:$F,'Septiembre 25'!$A:$A,A20) | F60: =H10+AQ10-SUMIFS('Octubre 25'!$F:$F,'Octubre 25'!$A:$A,A10)
A61: 99001 | B61: FÓRMULA EXTERNA 1 | C61: =SUMIFS('Mayo 25'!$E:$E,'Mayo 25'!$A:$A,A11) | D61: =+AB11+BK11 | E61: =SUMIFS('Septiembre 25'!$F:$F,'Septiembre 25'!$A:$A,A21) | F61: =H11+AQ11-SUMIFS('Octubre 25'!$F:$F,'Octubre 25'!$A:$A,A11)
A62: 99002 | B62: FÓRMULA EXTERNA 2 | C62: =SUMIFS('Mayo 25'!$E:$E,'Mayo 25'!$A:$A,A12) | D62: =+AB12+BK12 | E62: =SUMIFS('Septiembre 25'!$F:$F,'Septiembre 25'!$A:$A,A22) | F62: =H12+AQ12-SUMIFS('Octubre 25'!$F:$F,'Octubre 25'!$A:$A,A12)
A63: 99003 | B63: FÓRMULA EXTERNA 3 | C63: =SUMIFS('Mayo 25'!$E:$E,'Mayo 25'!$A:$A,A13) | D63: =+AB13+BK13 | E63: =SUMIFS('Septiembre 25'!$F:$F,'Septiembre 25'!$A:$A,A23) | F63: =H13+AQ13-SUMIFS('Octubre 25'!$F:$F,'Octubre 25'!$A:$A,A13)
A64: 99004 | B64: FÓRMULA EXTERNA 4 | C64: =SUMIFS('Mayo 25'!$E:$E,'Mayo 25'!$A:$A,A14) | D64: =+AB14+BK14 | E64: =SUMIFS('Septiembre 25'!$F:$F,'Septiembre 25'!$A:$A,A24) | F64: =H14+AQ14-SUMIFS('Octubre 25'!$F:$F,'Octubre 25'!$A:$A,A14)

Sheet Agregado
A1: Aromas y Sabores del Mediterráneo S.L.
A2: Sumas y Saldos AGREGADO 2024-2025
A4: Subcuenta | B4: Concepto | C4: Total Debe | D4: Total Haber | E4: Saldo Final
A5: 100 | B5: Capital social | C5: =SUMIFS('Mayo 25'!$D:$D,'Mayo 25'!$A:$A,A5) | D5: =SUMIFS('Mayo 25'!$E:$E,'Mayo 25'!$A:$A,A5) | E5: =+C5-D5
A6: 129 | B6: Resultado del ejercicio | C6: =SUMIFS('Mayo 25'!$D:$D,'Mayo 25'!$A:$A,A5) | D6: =SUMIFS('Mayo 25'!$E:$E,'Mayo 25'!$A:$A,A5) | E6: =+C5-D5
A7: 281 | B7: Amortización acumulada del inmovilizado material | C7: =SUMIFS('Mayo 25'!$D:$D,'Mayo 25'!$A:$A,A5) | D7: =SUMIFS('Mayo 25'!$E:$E,'Mayo 25'!$A:$A,A5) | E7: =+C5-D5
A8: 4720 | B8: H.P. IVA SOPORTADO | C8: =SUMIFS('Mayo 25'!$D:$D,'Mayo 25'!$A:$A,A5) | D8: =SUMIFS('Mayo 25'!$E:$E,'Mayo 25'!$A:$A,A5) | E8: =+C5-D5
A9: 4770 | B9: H.P. IVA REPERCUTIDO | C9: =SUMIFS('Mayo 25'!$D:$D,'Mayo 25'!$A:$A,A5) | D9: =SUMIFS('Mayo 25'!$E:$E,'Mayo 25'!$A:$A,A5) | E9: =+C5-D5
A10: 4751 | B10: H.P. Acreedora por IS | C10: =SUMIFS('Mayo 25'!$D:$D,'Mayo 25'!$A:$A,A5) | D10: =SUMIFS('Mayo 25'!$E:$E,'Mayo 25'!$A:$A,A5) | E10: =+C5-D5
A11: 4752 | B11: H.P. Acreedora por IRPF | C11: =SUMIFS('Mayo 25'!$D:$D,'Mayo 25'!$A:$A,A5) | D11: =SUMIFS('Mayo 25'!$E:$E,'Mayo 25'!$A:$A,A5) | E11: =+C5-D5
A12: 4760 | B12: Organismos de la Seguridad Social acreedores | C12: =SUMIFS('Mayo 25'!$D:$D,'Mayo 25'!$A:$A,A5) | D12: =SUMIFS('Mayo 25'!$E:$E,'Mayo 25'!$A:$A,A5) | E12: =+C5-D5
A13: 570 | B13: Caja, euros | C13: =SUMIFS('Mayo 25'!$D:$D,'Mayo 25'!$A:$A,A5) | D13: =SUMIFS('Mayo 25'!$E:$E,'Mayo 25'!$A:$A,A5) | E13: =+C5-D5
A14: 572 | B14: Bancos e instituciones de crédito c/c vista, euros | C14: =SUMIFS('Mayo 25'!$D:$D,'Mayo 25'!$A:$A,A5) | D14: =SUMIFS('Mayo 25'!$E:$E,'Mayo 25'!$A:$A,A5) | E14: =+C5-D5
A15: 600 | B15: Compras de mercaderías | C15: =SUMIFS('Mayo 25'!$D:$D,'Mayo 25'!$A:$A,A5) | D15: =SUMIFS('Mayo 25'!$E:$E,'Mayo 25'!$A:$A,A5) | E15: =+C5-D5
A16: 621 | B16: Arrendamientos y cánones | C16: =SUMIFS('Mayo 25'!$D:$D,'Mayo 25'!$A:$A,A5) | D16: =SUMIFS('Mayo 25'!$E:$E,'Mayo 25'!$A:$A,A5) | E16: =+C5-D5
A17: 622 | B17: Reparaciones y conservación | C17: =SUMIFS('Mayo 25'!$D:$D,'Mayo 25'!$A:$A,A5) | D17: =SUMIFS('Mayo 25'!$E:$E,'Mayo 25'!$A:$A,A5) | E17: =+C5-D5
A18: 623 | B18: Servicios de profesionales independientes | C18: =SUMIFS('Mayo 25'!$D:$D,'Mayo 25'!$A:$A,A5) | D18: =SUMIFS('Mayo 25'!$E:$E,'Mayo 25'!$A:$A,A5) | E18: =+C5-D5
A19: 624 | B19: Transportes | C19: =SUMIFS('Mayo 25'!$D:$D,'Mayo 25'!$A:$A,A5) | D19: =SUMIFS('Mayo 25'!$E:$E,'Mayo 25'!$A:$A,A5) | E19: =+C5-D5
A20: 625 | B20: Primas de seguros | C20: =SUMIFS('Mayo 25'!$D:$D,'Mayo 25'!$A:$A,A5) | D20: =SUMIFS('Mayo 25'!$E:$E,'Mayo 25'!$A:$A,A5) | E20: =+C5-D5
A21: 627 | B21: Publicidad, propaganda y RRPP | C21: =SUMIFS('Mayo 25'!$D:$D,'Mayo 25'!$A:$A,A5) | D21: =SUMIFS('Mayo 25'!$E:$E,'Mayo 25'!$A:$A,A5) | E21: =+C5-D5
A22: 628 | B22: Suministros | C22: =SUMIFS('Mayo 25'!$D:$D,'Mayo 25'!$A:$A,A5) | D22: =SUMIFS('Mayo 25'!$E:$E,'Mayo 25'!$A:$A,A5) | E22: =+C5-D5
A23: 629 | B23: Otros servicios | C23: =SUMIFS('Mayo 25'!$D:$D,'Mayo 25'!$A:$A,A5) | D23: =SUMIFS('Mayo 25'!$E:$E,'Mayo 25'!$A:$A,A5) | E23: =+C5-D5
A24: 630 | B24: Impuesto sobre beneficios | C24: =SUMIFS('Mayo 25'!$D:$D,'Mayo 25'!$A:$A,A5) | D24: =SUMIFS('Mayo 25'!$E:$E,'Mayo 25'!$A:$A,A5) | E24: =+C5-D5
A25: 631 | B25: Otros tributos | C25: =SUMIFS('Mayo 25'!$D:$D,'Mayo 25'!$A:$A,A5) | D25: =SUMIFS('Mayo 25'!$E:$E,'Mayo 25'!$A:$A,A5) | E25: =+C5-D5
A26: 640 | B26: Sueldos y salarios | C26: =SUMIFS('Mayo 25'!$D:$D,'Mayo 25'!$A:$A,A5) | D26: =SUMIFS('Mayo 25'!$E:$E,'Mayo 25'!$A:$A,A5) | E26: =+C5-D5
A27: 642 | B27: Seguridad Social a cargo de la empresa | C27: =SUMIFS('Mayo 25'!$D:$D,'Mayo 25'!$A:$A,A5) | D27: =SUMIFS('Mayo 25'!$E:$E,'Mayo 25'!$A:$A,A5) | E27: =+C5-D5
A28: 700 | B28: Ventas de mercaderías | C28: =SUMIFS('Mayo 25'!$D:$D,'Mayo 25'!$A:$A,A5) | D28: =SUMIFS('Mayo 25'!$E:$E,'Mayo 25'!$A:$A,A5) | E28: =+C5-D5
A29: 705 | B29: Prestaciones de servicios | C29: =SUMIFS('Mayo 25'!$D:$D,'Mayo 25'!$A:$A,A5) | D29: =SUMIFS('Mayo 25'!$E:$E,'Mayo 25'!$A:$A,A5) | E29: =+C5-D5
A30: 4300000001 | B30: BANCO SABADELL, S.A. | C30: =SUMIFS('Mayo 25'!$D:$D,'Mayo 25'!$A:$A,A5) | D30: =SUMIFS('Mayo 25'!$E:$E,'Mayo 25'!$A:$A,A5) | E30: =+C5-D5
A31: 4300000002 | B31: CAIXABANK, SA | C31: =SUMIFS('Mayo 25'!$D:$D,'Mayo 25'!$A:$A,A5) | D31: =SUMIFS('Mayo 25'!$E:$E,'Mayo 25'!$A:$A,A5) | E31: =+C5-D5
A32: 4300000003 | B32: PREVENPYME, SL | C32: =SUMIFS('Mayo 25'!$D:$D,'Mayo 25'!$A:$A,A5) | D32: =SUMIFS('Mayo 25'!$E:$E,'Mayo 25'!$A:$A,A5) | E32: =+C5-D5
A33: 4300000004 | B33: EVENTOS MEDITERRÁNEOS, SL | C33: =SUMIFS('Mayo 25'!$D:$D,'Mayo 25'!$A:$A,A5) | D33: =SUMIFS('Mayo 25'!$E:$E,'Mayo 25'!$A:$A,A5) | E33: =+C5-D5
A34: 4300000005 | B34: DISTRIBUCIONES BADIA | C34: =SUMIFS('Mayo 25'!$D:$D,'Mayo 25'!$A:$A,A5) | D34: =SUMIFS('Mayo 25'!$E:$E,'Mayo 25'!$A:$A,A5) | E34: =+C5-D5
A35: 4300000006 | B35: INMOBILIARIA TUSET SLU | C35: =SUMIFS('Mayo 25'!$D:$D,'Mayo 25'!$A:$A,A5) | D35: =SUMIFS('Mayo 25'!$E:$E,'Mayo 25'!$A:$A,A5) | E35: =+C5-D5
A36: 4300000007 | B36: ASESORÍA MIRALLES | C36: =SUMIFS('Mayo 25'!$D:$D,'Mayo 25'!$A:$A,A5) | D36: =SUMIFS('Mayo 25'!$E:$E,'Mayo 25'!$A:$A,A5) | E36: =+C5-D5
A37: 4300000008 | B37: FRUTAS CARIÑENA S.L. | C37: =SUMIFS('Mayo 25'!$D:$D,'Mayo 25'!$A:$A,A5) | D37: =SUMIFS('Mayo 25'!$E:$E,'Mayo 25'!$A:$A,A5) | E37: =+C5-D5
A38: 4300000009 | B38: ARNAU TORRES DKAIDEK | C38: =SUMIFS('Mayo 25'!$D:$D,'Mayo 25'!$A:$A,A5) | D38: =SUMIFS('Mayo 25'!$E:$E,'Mayo 25'!$A:$A,A5) | E38: =+C5-D5
A39: 4300000010 | B39: NATALIA POLO CHOCANO | C39: =SUMIFS('Mayo 25'!$D:$D,'Mayo 25'!$A:$A,A5) | D39: =SUMIFS('Mayo 25'!$E:$E,'Mayo 25'!$A:$A,A5) | E39: =+C5-D5
A40: 4300000011 | B40: ADRIANA HUERTAS | C40: =SUMIFS('Mayo 25'!$D:$D,'Mayo 25'!$A:$A,A5) | D40: =SUMIFS('Mayo 25'!$E:$E,'Mayo 25'!$A:$A,A5) | E40: =+C5-D5
A41: 4300000012 | B41: HORTENSIA HERRERO | C41: =SUMIFS('Mayo 25'!$D:$D,'Mayo 25'!$A:$A,A5) | D41: =SUMIFS('Mayo 25'!$E:$E,'Mayo 25'!$A:$A,A5) | E41: =+C5-D5
...
